<mujoco model="cricket">
  <compiler angle="degree" coordinate="local" inertiafromgeom="true"/>
  <option integrator="RK4" timestep="0.01"/>

  <custom>
    <numeric data="0.0 0.0 0.55 1.0 0.0 0.0 0.0 0.0 1.0 0.0 -1.0 0.0 -1.0 0.0 1.0" name="init_qpos"/>
  </custom>

  <default>
    <joint armature="1" damping="1" limited="true"/>
    <geom conaffinity="0" condim="3" density="5.0" friction="1 0.5 0.5" margin="0.01" rgba="0.8 0.6 0.4 1"/>
  </default>

  <asset>
    <texture builtin="gradient" height="100" rgb1="1 1 1" rgb2="0 0 0" type="skybox" width="100"/>
    <texture builtin="flat" height="1278" mark="cross" markrgb="1 1 1" name="texgeom" random="0.01" rgb1="0.8 0.6 0.4" rgb2="0.8 0.6 0.4" type="cube" width="127"/>
    <texture builtin="checker" height="100" name="texplane" rgb1=".25 .25 .25" rgb2=".3 .3 .3" type="2d" width="100" mark="cross" markrgb=".8 .8 .8"/>
    <material name="MatPlane" reflectance="0.5" shininess="1" specular="1" texrepeat="60 60" texture="texplane"/>
    <material name="geom" texture="texgeom" texuniform="true"/>
  </asset>

  <worldbody>
    <light cutoff="100" diffuse="1 1 1" dir="-0 0 -1.3" directional="true" exponent="1" pos="0 0 1.3" specular=".1 .1 .1"/>
    <geom conaffinity="1" condim="3" material="MatPlane" name="floor" pos="0 0 0" rgba="0.8 0.8 0.8 1" size="40 40 40" type="plane"/>
    <body name="torso" pos="0 0 0.75">
      <camera name="track" mode="trackcom" pos="0 -3 0.3" xyaxes="1 0 0 0 0 1"/>
      <geom name="torso_geom" type="box" pos="0 0 0" size=".3 .2 .08"/>
      <joint armature="0" damping="0" limited="false" margin="0.01" name="root" pos="0 0 0" type="free"/>

      <body name="LF_leg" pos="0 0 0">
        <geom fromto="0.0 0.0 0.0 0.3 0.2 0.0" name="LF_aux_geom" size="0.08" type="capsule"/>
        <body name="LF_aux" pos="0.3 0.2 0">
          <joint axis="1 -1 0" name="LF_CTr" pos="0.0 0.0 0.0" range="-10 10" type="hinge"/>
          <joint axis="0 0 -1" name="LF_hip" pos="0.0 0.0 0.0" range="-10 10" type="hinge"/>
          <geom fromto="0.0 0.0 0.0 0.2 0.2 0.0" name="LF_femur_geom" size="0.08" type="capsule"/>
          <body pos="0.2 0.2 0.0">
            <joint axis="-1 0 0" name="LF_knee" pos="0.0 0.0 0.0" range="70 90" type="hinge"/>
            <geom fromto="0.0 0.0 0.0 0.2 0.2 0.0" name="LF_tibia_geom" size="0.08" type="capsule"/>
          </body>
        </body>
      </body>

      <body name="RF_leg" pos="0 0 0">
        <geom fromto="0.0 0.0 0.0 0.3 -0.2 0.0" name="RF_aux_geom" size="0.08" type="capsule"/>
        <body name="RF_aux" pos="0.3 -0.2 0">
          <joint axis="-1 -1 0" name="RF_CTr" pos="0.0 0.0 0.0" range="-10 10" type="hinge"/>
          <joint axis="0 0 1" name="RF_hip" pos="0.0 0.0 0.0" range="-10 10" type="hinge"/>
          <geom fromto="0.0 0.0 0.0 0.2 -0.2 0.0" name="RF_femur_geom" size="0.08" type="capsule"/>
          <body pos="0.2 -0.2 0.0">
            <joint axis="1 0 0" name="RF_knee" pos="0.0 0.0 0.0" range="70 90" type="hinge"/>
            <geom fromto="0.0 0.0 0.0 0.2 -0.2 0.0" name="RF_tibia_geom" size="0.08" type="capsule"/>
          </body>
        </body>
      </body>

      <body name="LM_leg" pos="0 0 0">
        <geom fromto="0.0 0.0 0.0 0.0 0.2 0.0" name="LM_aux_geom" size="0.08" type="capsule"/>
        <body name="LM_aux" pos="0.0 0.2 0">
          <joint axis="1 0 0" name="LM_CTr" pos="0.0 0.0 0.0" range="-10 20" type="hinge"/>
          <joint axis="0 0 1" name="LM_hip" pos="0.0 0.0 0.0" range="-30 30" type="hinge"/>
          <geom fromto="0.0 0.0 0.0 0.0 0.3 0.0" name="LM_femur_geom" size="0.08" type="capsule"/>
          <body pos="0.0 0.3 0.0">
            <joint axis="-1 0 0" name="LM_knee" pos="0.0 0.0 0.0" range="70 80" type="hinge"/>
            <geom fromto="0.0 0.0 0.0 0.0 0.3 0.0" name="LM_tibia_geom" size="0.08" type="capsule"/>
          </body>
        </body>
      </body>

      <body name="RM_leg" pos="0 0 0">
        <geom fromto="0.0 0.0 0.0 0.0 -0.2 0.0" name="RM_aux_geom" size="0.08" type="capsule"/>
        <body name="RM_aux" pos="0.0 -0.2 0">
          <joint axis="-1 0 0" name="RM_CTr" pos="0.0 0.0 0.0" range="-10 20" type="hinge"/>
          <joint axis="0 0 1" name="RM_hip" pos="0.0 0.0 0.0" range="-30 30" type="hinge"/>
          <geom fromto="0.0 0.0 0.0 0.0 -0.3 0.0" name="RM_femur_geom" size="0.08" type="capsule"/>
          <body pos="0.0 -0.3 0.0">
            <joint axis="1 0 0" name="RM_knee" pos="0.0 0.0 0.0" range="70 80" type="hinge"/>
            <geom fromto="0.0 0.0 0.0 0.0 -0.3 0.0" name="RM_tibia_geom" size="0.08" type="capsule"/>
          </body>
        </body>
      </body>

      <body name="LH_leg" pos="0 0 0">
        <geom fromto="0.0 0.0 0.0 -0.3 0.2 0.0" name="LH_aux_geom" size="0.08" type="capsule"/>
        <body name="LH_aux" pos="-0.3 0.2 0">          
          <joint axis="3 5 0" name="LH_CTr" pos="0.0 0.0 0.0" range="-10 0" type="hinge"/>
          <joint axis="0 0 1" name="LH_hip" pos="0.0 0.0 0.0" range="0 10" type="hinge"/>
          <geom fromto="0.0 0.0 0.0 -0.45 0.25 0.3" name="LH_femur_geom" size="0.08" type="capsule"/>
          <body pos="-0.45 0.25 0.3">
            <joint axis="-1 0 0" name="LH_knee" pos="0.0 0.0 0.0" range="70 150" type="hinge"/>
            <geom fromto="0.0 0.0 0.0 -0.45 0.25 0.0" name="LH_tibia_geom" size="0.08" type="capsule"/>
          </body>
        </body>
      </body>

      <body name="RH_leg" pos="0 0 0">
        <geom fromto="0.0 0.0 0.0 -0.3 -0.2 0.0" name="RH_aux_geom" size="0.08" type="capsule"/>
        <body name="RH_aux" pos="-0.3 -0.2 0">
          <joint axis="-3 5 0" name="RH_CTr" pos="0.0 0.0 0.0" range="-10 0" type="hinge"/>
          <joint axis="0 0 -1" name="RH_hip" pos="0.0 0.0 0.0" range="0 10" type="hinge"/>
          <geom fromto="0.0 0.0 0.0 -0.45 -0.25 0.3" name="RH_femur_geom" size="0.08" type="capsule"/>
          <body pos="-0.45 -0.25 0.3">
            <joint axis="1 0 0" name="RH_knee" pos="0.0 0.0 0.0" range="70 150" type="hinge"/>
            <geom fromto="0.0 0.0 0.0 -0.45 -0.25 0.0" name="RH_tibia_geom" size="0.08" type="capsule"/>
          </body>
        </body>
      </body>
    
    </body>
  </worldbody>

  <actuator>
    <motor ctrllimited="true" ctrlrange="-1.0 1.0" joint="LF_hip" gear="150"/>
    <motor ctrllimited="true" ctrlrange="-1.0 1.0" joint="LF_knee" gear="150"/>
    <motor ctrllimited="true" ctrlrange="-1.0 1.0" joint="RF_hip" gear="150"/>
    <motor ctrllimited="true" ctrlrange="-1.0 1.0" joint="RF_knee" gear="150"/>
    <motor ctrllimited="true" ctrlrange="-1.0 1.0" joint="LM_hip" gear="150"/>
    <motor ctrllimited="true" ctrlrange="-1.0 1.0" joint="LM_knee" gear="150"/>
    <motor ctrllimited="true" ctrlrange="-1.0 1.0" joint="RM_hip" gear="150"/>
    <motor ctrllimited="true" ctrlrange="-1.0 1.0" joint="RM_knee" gear="150"/>
    <motor ctrllimited="true" ctrlrange="-1.0 1.0" joint="LH_hip" gear="150"/>
    <motor ctrllimited="true" ctrlrange="-1.0 1.0" joint="LH_knee" gear="150"/>
    <motor ctrllimited="true" ctrlrange="-1.0 1.0" joint="RH_hip" gear="150"/>
    <motor ctrllimited="true" ctrlrange="-1.0 1.0" joint="RH_knee" gear="150"/>
    <motor ctrllimited="true" ctrlrange="-1.0 1.0" joint="LH_CTr" gear="150"/>
    <motor ctrllimited="true" ctrlrange="-1.0 1.0" joint="RH_CTr" gear="150"/>
    <motor ctrllimited="true" ctrlrange="-1.0 1.0" joint="LM_CTr" gear="150"/>
    <motor ctrllimited="true" ctrlrange="-1.0 1.0" joint="RM_CTr" gear="150"/>
    <motor ctrllimited="true" ctrlrange="-1.0 1.0" joint="LF_CTr" gear="150"/>
    <motor ctrllimited="true" ctrlrange="-1.0 1.0" joint="RF_CTr" gear="150"/>
  </actuator>
</mujoco>