<mujoco model="cricket2d">
  <compiler angle="degree" coordinate="local" inertiafromgeom="true"/>
  <option integrator="RK4" timestep="0.01"/>

  <custom>
    <numeric data="0.0 0.0 0.55 1.0 0.0 0.0 0.0 0.0 1.0 0.0 -1.0 0.0 -1.0 0.0 1.0" name="init_qpos"/>
  </custom>

  <default>
    <joint armature="1" damping="1" limited="true"/>
    <geom conaffinity="0" condim="3" density="5.0" friction="1 0.5 0.5" margin="0.01" rgba="0.8 0.6 0.4 1"/>
  </default>

  <asset>
    <texture builtin="gradient" height="100" rgb1="1 1 1" rgb2="0 0 0" type="skybox" width="100"/>
    <texture builtin="flat" height="1278" mark="cross" markrgb="1 1 1" name="texgeom" random="0.01" rgb1="0.8 0.6 0.4" rgb2="0.8 0.6 0.4" type="cube" width="127"/>
    <texture builtin="checker" height="100" name="texplane" rgb1=".25 .25 .25" rgb2=".3 .3 .3" type="2d" width="100" mark="cross" markrgb=".8 .8 .8"/>
    <material name="MatPlane" reflectance="0.5" shininess="1" specular="1" texrepeat="60 60" texture="texplane"/>
    <material name="geom" texture="texgeom" texuniform="true"/>
  </asset>

  <worldbody>
    <light cutoff="100" diffuse="1 1 1" dir="-0 0 -1.3" directional="true" exponent="1" pos="0 0 1.3" specular=".1 .1 .1"/>
    <geom conaffinity="1" friction="0 0 0" condim="3" material="MatPlane" name="floor" pos="0 0 0" rgba="0.8 0.8 0.8 1" size="40 40 40" type="plane"/>
    <body name="aux" pos="0 0 0.1">
      <joint axis="1 0 0" name="slide_x" pos="0 0 0" limited="false" type="slide"/>
      <joint axis="0 1 0" name="slide_y" pos="0 0 0" limited="false" type="slide"/>
      <geom name="aux_geom" size="0.08" type="sphere"/>
        <body name="torso" pos="0 0 0">
            <joint axis="0 0 -1" name="abdomen_z" pos="0 0 0" limited="false" type="hinge"/>
            <geom name="torso_geom" type="box" pos="0 0 0" size=".3 .2 .08"/>

      <body name="LF_leg" pos="0 0 0">
        <geom fromto="0.0 0.0 0.0 0.3 0.2 0.0" name="LF_aux_geom" size="0.08" type="capsule"/>
        <body name="LF_femur" pos="0.3 0.2 0">
          <joint axis="0 0 -1" name="LF_hip" pos="0.0 0.0 0.0" range="-45 110" type="hinge"/>
          <geom fromto="0.0 0.0 0.0 0.0 0.28 0.0" name="LF_femur_geom" size="0.08" type="capsule"/>
          <body name="LF_tibia" pos="0.0 0.28 0.0">
            <joint axis="0 0 -1" name="LF_knee" pos="0.0 0.0 0.0" range="-180 180" type="hinge"/>
            <geom fromto="0.0 0.0 0.0 0.0 0.28 0.0" name="LF_tibia_geom" size="0.08" type="capsule"/>
            <body name="LF_tip" pos="0.0 0.28. 0.0">
                <geom name="LF_tip_geom" pos="0.0 0.0 -0.08" size="0.02" type="sphere" friction="1 1 0.5"/>
            </body>
          </body>
        </body>
      </body>

      <body name="RF_leg" pos="0 0 0">
        <geom fromto="0.0 0.0 0.0 0.3 -0.2 0.0" name="RF_aux_geom" size="0.08" type="capsule"/>
        <body name="RF_femur" pos="0.3 -0.2 0">
          <joint axis="0 0 -1" name="RF_hip" pos="0.0 0.0 0.0" range="-110 45" type="hinge"/>
          <geom fromto="0.0 0.0 0.0 0.0 -0.28 0.0" name="RF_femur_geom" size="0.08" type="capsule"/>
          <body name="RF_tibia" pos="0.0 -0.28 0.0">
            <joint axis="0 0 -1" name="RF_knee" pos="0.0 0.0 0.0" range="-180 180" type="hinge"/>
            <geom fromto="0.0 0.0 0.0 0.0 -0.28 0.0" name="RF_tibia_geom" size="0.08" type="capsule"/>
            <body name="RF_tip" pos="0.0 -0.28. 0.0">
                <geom name="RF_tip_geom" pos="0.0 0.0 -0.08" size="0.02" type="sphere" friction="1 1 0.5"/>
            </body>
          </body>
        </body>
      </body>

      <body name="LM_leg" pos="0 0 0">
        <geom fromto="0.0 0.0 0.0 0.0 0.2 0.0" name="LM_aux_geom" size="0.08" type="capsule"/>
        <body name="LM_femur" pos="0.0 0.2 0">
          <joint axis="0 0 -1" name="LM_hip" pos="0.0 0.0 0.0" range="-65 55" type="hinge"/>
          <geom fromto="0.0 0.0 0.0 0.0 0.3 0.0" name="LM_femur_geom" size="0.08" type="capsule"/>
          <body name="LM_tibia" pos="0.0 0.3 0.0">
            <joint axis="0 0 -1" name="LM_knee" pos="0.0 0.0 0.0" range="-180 180" type="hinge"/>
            <geom fromto="0.0 0.0 0.0 0.0 0.3 0.0" name="LM_tibia_geom" size="0.08" type="capsule"/>
            <body name="LM_tip" pos="0.0 0.3 0.0">
                <geom name="LM_tip_geom" pos="0.0 0.0 -0.08" size="0.02" type="sphere" friction="1 1 0.5"/>
            </body>
          </body>
        </body>
      </body>

      <body name="RM_leg" pos="0 0 0">
        <geom fromto="0.0 0.0 0.0 0.0 -0.2 0.0" name="RM_aux_geom" size="0.08" type="capsule"/>
        <body name="RM_femur" pos="0.0 -0.2 0">
          <joint axis="0 0 -1" name="RM_hip" pos="0.0 0.0 0.0" range="-55 65" type="hinge"/>
          <geom fromto="0.0 0.0 0.0 0.0 -0.3 0.0" name="RM_femur_geom" size="0.08" type="capsule"/>
          <body name="RM_tibia" pos="0.0 -0.3 0.0">
            <joint axis="0 0 -1" name="RM_knee" pos="0.0 0.0 0.0" range="-180 180" type="hinge"/>
            <geom fromto="0.0 0.0 0.0 0.0 -0.3 0.0" name="RM_tibia_geom" size="0.08" type="capsule"/>
            <body name="RM_tip" pos="0.0 -0.3 0.0">
                <geom name="RM_tip_geom" pos="0.0 0.0 -0.08" size="0.02" type="sphere" friction="1 1 0.5"/>
            </body>
          </body>
        </body>
      </body>

      <body name="LH_leg" pos="0 0 0">
        <geom fromto="0.0 0.0 0.0 -0.3 0.2 0.0" name="LH_aux_geom" size="0.08" type="capsule"/>
        <body name="LH_femur" pos="-0.3 0.2 0">          
          <joint axis="0 0 -1" name="LH_hip" pos="0.0 0.0 0.0" range="-115 15" type="hinge"/>
          <geom fromto="0.0 0.0 0.0 0.0 0.51 0" name="LH_femur_geom" size="0.08" type="capsule"/>
          <body name="LH_tibia" pos="0.0 0.51 0">
            <joint axis="0 0 -1" name="LH_knee" pos="0.0 0.0 0.0" range="-180 0" type="hinge"/>
            <geom fromto="0.0 0.0 0.0 0.0 0.51 0" name="LH_tibia_geom" size="0.08" type="capsule"/>
            <body name="LH_tip" pos="0.0 0.51 0.0">
                <geom name="LH_tip_geom" pos="0.0 0.0 -0.08" size="0.02" type="sphere" friction="1 1 0.5"/>
            </body>
          </body>
        </body>
      </body>

      <body name="RH_leg" pos="0 0 0">
        <geom fromto="0.0 0.0 0.0 -0.3 -0.2 0.0" name="RH_aux_geom" size="0.08" type="capsule"/>
        <body name="RH_femur" pos="-0.3 -0.2 0">
          <joint axis="0 0 -1" name="RH_hip" pos="0.0 0.0 0.0" range="-15 115" type="hinge"/>
          <geom fromto="0.0 0.0 0.0 0.0 -0.51 0" name="RH_femur_geom" size="0.08" type="capsule"/>
          <body name="RH_tibia" pos="0.0 -0.51 0">
            <joint axis="0 0 -1" name="RH_knee" pos="0.0 0.0 0.0" range="0 180" type="hinge"/>
            <geom fromto="0.0 0.0 0.0 0.0 -0.51 0" name="RH_tibia_geom" size="0.08" type="capsule"/>
            <body name="RH_tip" pos="0.0 -0.51 0.0">
                <geom name="RH_tip_geom" pos="0.0 0.0 -0.08" size="0.02" type="sphere" friction="1 1 0.5"/>
            </body>
          </body>
        </body>
      </body>
    
        </body>
    </body>
    <camera name="track" mode="trackcom" target="aux" pos="0 0 30" xyaxes="1 0 0 0 1 0"/>
    <camera name="fix" mode="fixed" pos="0 -7 15" xyaxes="1 0 0 0 2 1"/>
  </worldbody>

  <actuator>
    <position ctrllimited="true" ctrlrange="-0.7853981634 1.919862177" joint="LF_hip" gear="1" kp="30000"/>
    <position ctrllimited="true" ctrlrange="-1.134464014 0.9599310886" joint="LM_hip" gear="1" kp="30000"/>
    <position ctrllimited="true" ctrlrange="-2.00712864 0.2617993878" joint="LH_hip" gear="1" kp="30000"/>
    <position ctrllimited="true" ctrlrange="-1.919862177 0.7853981634" joint="RF_hip" gear="1" kp="30000"/>
    <position ctrllimited="true" ctrlrange="-0.9599310886 1.134464014" joint="RM_hip" gear="1" kp="30000"/>
    <position ctrllimited="true" ctrlrange="-0.2617993878 2.00712864" joint="RH_hip" gear="1" kp="30000"/>
    <position ctrllimited="true" ctrlrange="-3.141592654 3.141592654" joint="LF_knee" gear="1" kp="30000"/>
    <position ctrllimited="true" ctrlrange="-3.141592654 3.141592654" joint="LM_knee" gear="1" kp="30000"/>
    <position ctrllimited="true" ctrlrange="-3.141592654 0.0" joint="LH_knee" gear="1" kp="30000"/>
    <position ctrllimited="true" ctrlrange="-3.141592654 3.141592654" joint="RF_knee" gear="1" kp="30000"/>
    <position ctrllimited="true" ctrlrange="-3.141592654 3.141592654" joint="RM_knee" gear="1" kp="30000"/>
    <position ctrllimited="true" ctrlrange="0.0 3.141592654" joint="RH_knee" gear="1" kp="30000"/>
    <position ctrllimited="false" joint="slide_x" gear="1" kp="70000"/>
    <position ctrllimited="false" joint="slide_y" gear="1" kp="70000"/>
    <position ctrllimited="false" joint="abdomen_z" gear="1" kp="70000"/>
    </actuator>
</mujoco>