<mujoco model="stick insect">
  <compiler angle="degree" coordinate="local" inertiafromgeom="true"/>
  <option integrator="RK4" timestep="0.005"/> <!-- frequency [200,50] -->

  <custom>
    <numeric data="0.10681971 -0.20482576 0.76341401 0.92561184 0.18595086 0.18452993 
0.78049568 0.01004119 0.00413513 -0.03130112 -0.18171205 0.21024531 
-0.19540428 0.15524787 -0.6086322 0.4715757 -0.23915008 0.06885989 
-1.01172582 0.99137151 0.1567984 0.60833356 -0.45790772 -0.41003116 " name="init_qpos"/>
  </custom>

  <default>
    <joint armature="1" damping="1" limited="true"/>
    <geom conaffinity="0" condim="3" density="5.0" friction="1 0.5 0.5" margin="0.01" rgba="0.8 0.6 0.4 1"/>
  </default>

  <asset>
    <texture builtin="gradient" height="100" rgb1="1 1 1" rgb2="0 0 0" type="skybox" width="100"/>
    <texture builtin="flat" height="1278" mark="cross" markrgb="1 1 1" name="texgeom" random="0.01" rgb1="0.8 0.6 0.4" rgb2="0.8 0.6 0.4" type="cube" width="127"/>
    <texture builtin="checker" height="100" name="texplane" rgb1=".25 .25 .25" rgb2=".3 .3 .3" type="2d" width="100" mark="cross" markrgb=".8 .8 .8"/>
    <material name="MatPlane" reflectance="0.5" shininess="1" specular="1" texrepeat="60 60" texture="texplane"/>
    <material name="geom" texture="texgeom" texuniform="true"/>
  </asset>

  <worldbody>
    <light cutoff="100" diffuse="1 1 1" dir="-0 0 -1.3" directional="true" exponent="1" pos="0 0 1.3" specular=".1 .1 .1"/>
    <geom conaffinity="1" condim="3" material="MatPlane" name="floor" pos="0 0 0" rgba="0.8 0.8 0.8 1" size="40 40 40" type="plane"/>
    <camera name="side" mode="fixed" pos="7 -17 2" xyaxes="1 0 0 0 0 1"/>
    <camera name="top" mode="fixed" pos="5 0 20" xyaxes="1 0 0 0 1 0"/>
    <camera name="fixed float" mode="fixed" pos="-2 -10 6" xyaxes="1 0 0 0 0 1"/>

    <body name="torso" pos="0 0 2">
      <geom name="head_geom" pos="0 0 0" fromto="0.0 0.0 0.0 0.44 0.0 0.0" size="0.06" type="capsule"/>
      <geom name="T1_geom" pos="0 0 0" fromto="0.0 0.0 0.0 -0.38 0.0 -0.08" size="0.06" type="capsule"/>
      <geom name="T2_geom" pos="0 0 0" fromto="-0.38 0.0 -0.08 -2.1 0.0 -0.46" size="0.06" type="capsule"/>
      <geom name="T3_geom" pos="0 0 0" fromto="-2.1 0.0 -0.46 -3.3 0.0 -0.56" size="0.06" type="capsule"/>
      <joint armature="0" damping="0" limited="false" margin="0.01" name="root" pos="0 0 0" type="free"/>

      <body name="LF_leg" pos="-0.19 0 -0.04">
        <geom fromto="0.0 0.0 0.0 0.0 0.13 0.0" name="LF_cox_geom" size="0.05" type="capsule"/>
        <joint axis="0 -1 0" name="LF_Sup" pos="0.0 0.0 0.0" range="-7 24" type="hinge" />
        <site name="LF_Sup_site" pos="0 0 0" size="0.01"/>
        <body name="LF_femur" pos="0.0 0.13 0">
          <joint axis="1 0 0" name="LF_CTr" pos="0.0 0.0 0.0" range="-25 32" type="hinge"/>
          <joint axis="0 0 -1" name="LF_ThC" pos="0.0 0.0 0.0" range="-5 71" type="hinge"/>
          <site name="LF_CTr_site" pos="0 0 0" size="0.01"/>
          <site name="LF_ThC_site" pos="0 0 0" size="0.01"/>
          <geom fromto="0.0 0.0 0.0 0.0 1.58 0.0" name="LF_femur_geom" size="0.06" type="capsule"/>
          <body name="LF_tibia" pos="0.0 1.58 0.0">
            <joint axis="1 0 0" name="LF_FTi" pos="0.0 0.0 0.0" range="-43 56" type="hinge"/>
            <site name="LF_FTi_site" pos="0 0 0" size="0.01"/>
            <geom fromto="0.0 0.0 0.0 0.0 0.0 -1.50" name="LF_tibia_geom" size="0.03" type="capsule"/>
          </body>
        </body>
      </body>

      <body name="RF_leg" pos="-0.19 0 -0.04">
        <geom fromto="0.0 0.0 0.0 0.0 -0.13 0.0" name="RF_cox_geom" size="0.05" type="capsule"/>
        <joint axis="0 -1 0" name="RF_Sup" pos="0.0 0.0 0.0" range="-7 24" type="hinge" />
        <site name="RF_Sup_site" pos="0 0 0" size="0.01"/>
        <body name="RF_femur" pos="0.0 -0.13 0">
          <joint axis="-1 0 0" name="RF_CTr" pos="0.0 0.0 0.0" range="-25 32" type="hinge"/>
          <joint axis="0 0 1" name="RF_ThC" pos="0.0 0.0 0.0" range="-5 71" type="hinge"/>
          <site name="RF_CTr_site" pos="0 0 0" size="0.01"/>
          <site name="RF_ThC_site" pos="0 0 0" size="0.01"/>
          <geom fromto="0.0 0.0 0.0 0.0 -1.58 0.0" name="RF_femur_geom" size="0.06" type="capsule"/>
          <body name="RF_tibia" pos="0.0 -1.58 0.0">
            <joint axis="-1 0 0" name="RF_FTi" pos="0.0 0.0 0.0" range="-43 56" type="hinge"/>
            <site name="RF_FTi_site" pos="0 0 0" size="0.01"/>
            <geom fromto="0.0 0.0 0.0 0.0 0.0 -1.50" name="RF_tibia_geom" size="0.03" type="capsule"/>
          </body>
        </body>
      </body>

      <body name="LM_leg" pos="-2.1 0.0 -0.46">
        <geom fromto="0.0 0.0 0.0 0.0 0.14 0.0" name="LM_cox_geom" size="0.05" type="capsule" />
        <joint axis="0 -1 0" name="LM_Sup" pos="0.0 0.0 0.0" range="-26 37" type="hinge" />
        <site name="LM_Sup_site" pos="0 0 0" size="0.01"/>
        <body name="LM_femur" pos="0.0 0.14 0">
          <joint axis="1 0 0" name="LM_CTr" pos="0.0 0.0 0.0" range="-24 34" type="hinge"/>
          <joint axis="0 0 -1" name="LM_ThC" pos="0.0 0.0 0.0" range="-48 30" type="hinge"/>
          <site name="LM_CTr_site" pos="0 0 0" size="0.01"/>
          <site name="LM_ThC_site" pos="0 0 0" size="0.01"/>
          <geom fromto="0.0 0.0 0.0 0.0 1.16 0.0" name="LM_femur_geom" size="0.06" type="capsule"/>
          <body name="LM_tibia" pos="0.0 1.16 0.0">
            <joint axis="1 0 0" name="LM_FTi" pos="0.0 0.0 0.0" range="-50 79" type="hinge"/>
            <site name="LM_FTi_site" pos="0 0 0" size="0.01"/>
            <geom fromto="0.0 0.0 0.0 0.0 0.0 -1.12" name="LM_tibia_geom" size="0.03" type="capsule"/>
          </body>
        </body>
      </body>

      <body name="RM_leg" pos="-2.1 0.0 -0.46">
        <geom fromto="0.0 0.0 0.0 0.0 -0.14 0.0" name="RM_cox_geom" size="0.05" type="capsule" />
        <joint axis="0 -1 0" name="RM_Sup" pos="0.0 0.0 0.0" range="-26 37" type="hinge" />
        <site name="RM_Sup_site" pos="0 0 0" size="0.01"/>
        <body name="RM_femur" pos="0.0 -0.14 0">
          <joint axis="-1 0 0" name="RM_CTr" pos="0.0 0.0 0.0" range="-24 34" type="hinge"/>
          <joint axis="0 0 1" name="RM_ThC" pos="0.0 0.0 0.0" range="-48 30" type="hinge"/>
          <site name="RM_CTr_site" pos="0 0 0" size="0.01"/>  
          <site name="RM_ThC_site" pos="0 0 0" size="0.01"/>
          <geom fromto="0.0 0.0 0.0 0.0 -1.16 0.0" name="RM_femur_geom" size="0.06" type="capsule"/>
          <body name="RM_tibia" pos="0.0 -1.16 0.0">
            <joint axis="-1 0 0" name="RM_FTi" pos="0.0 0.0 0.0" range="-50 79" type="hinge"/>
            <site name="RM_FTi_site" pos="0 0 0" size="0.01"/>
            <geom fromto="0.0 0.0 0.0 0.0 0.0 -1.12" name="RM_tibia_geom" size="0.03" type="capsule"/>
          </body>
        </body>
      </body>

      <body name="LH_leg" pos="-3.3 0.0 -0.56">
        <geom fromto="0.0 0.0 0.0 0.0 0.15 0.0" name="LH_cox_geom" size="0.05" type="capsule"/>
        <joint axis="0 -1 0" name="LH_Sup" pos="0.0 0.0 0.0" range="-18 20" type="hinge" />
        <site name="LH_Sup_site" pos="0 0 0" size="0.01"/>
        <body name="LH_femur" pos="0.0 0.15 0">
          <joint axis="1 0 0" name="LH_CTr" pos="0.0 0.0 0.0" range="-10 50" type="hinge"/>
          <joint axis="0 0 -1" name="LH_ThC" pos="0.0 0.0 0.0" range="-65 -10" type="hinge"/>
          <site name="LH_CTr_site" pos="0 0 0" size="0.01"/>
          <site name="LH_ThC_site" pos="0 0 0" size="0.01"/>
          <geom fromto="0.0 0.0 0.0 0.0 1.39 0.0" name="LH_femur_geom" size="0.06" type="capsule"/>
          <body name="LH_tibia" pos="0.0 1.39 0.0">
            <joint axis="1 0 0" name="LH_FTi" pos="0.0 0.0 0.0" range="-51 78" type="hinge"/>
            <site name="LH_FTi_site" pos="0 0 0" size="0.01"/>
            <geom fromto="0.0 0.0 0.0 0.0 0.0 -1.41" name="LH_tibia_geom" size="0.03" type="capsule"/>
          </body>
        </body>
      </body>

      <body name="RH_leg" pos="-3.3 0.0 -0.56">
        <geom fromto="0.0 0.0 0.0 0.0 -0.15 0.0" name="RH_cox_geom" size="0.05" type="capsule"/>
        <joint axis="0 -1 0" name="RH_Sup" pos="0.0 0.0 0.0" range="-18 20" type="hinge" />
        <site name="RH_Sup_site" pos="0 0 0" size="0.01"/>
        <body name="RH_femur" pos="0.0 -0.15 0">
          <joint axis="-1 0 0" name="RH_CTr" pos="0.0 0.0 0.0" range="-10 50" type="hinge"/>
          <joint axis="0 0 1" name="RH_ThC" pos="0.0 0.0 0.0" range="-65 -10" type="hinge"/>
          <site name="RH_CTr_site" pos="0 0 0" size="0.01"/>
          <site name="RH_ThC_site" pos="0 0 0" size="0.01"/>
          <geom fromto="0.0 0.0 0.0 0.0 -1.39 0.0" name="RH_femur_geom" size="0.06" type="capsule"/>
          <body name="RH_tibia" pos="0.0 -1.39 0.0">
            <joint axis="-1 0 0" name="RH_FTi" pos="0.0 0.0 0.0" range="-51 78" type="hinge"/>
            <site name="RH_FTi_site" pos="0 0 0" size="0.01"/>
            <geom fromto="0.0 0.0 0.0 0.0 0.0 -1.41" name="RH_tibia_geom" size="0.03" type="capsule"/>
          </body>
        </body>
      </body>
    
    
    </body>
  </worldbody>

  <actuator>
    <position name="LF_Sup" ctrllimited="true" ctrlrange="-3.141592654 3.141592654" joint="LF_Sup" gear="1" kp="30000"/>
    <position name="LM_Sup" ctrllimited="true" ctrlrange="-3.141592654 3.141592654" joint="LM_Sup" gear="1" kp="30000"/>
    <position name="LH_Sup" ctrllimited="true" ctrlrange="-3.141592654 3.141592654" joint="LH_Sup" gear="1" kp="30000"/>
    <position name="RF_Sup" ctrllimited="true" ctrlrange="-3.141592654 3.141592654" joint="RF_Sup" gear="1" kp="30000"/>
    <position name="RM_Sup" ctrllimited="true" ctrlrange="-3.141592654 3.141592654" joint="RM_Sup" gear="1" kp="30000"/>
    <position name="RH_Sup" ctrllimited="true" ctrlrange="-3.141592654 3.141592654" joint="RH_Sup" gear="1" kp="30000"/>

    <position name="LF_CTr" ctrllimited="true" ctrlrange="-3.141592654 3.141592654" joint="LF_CTr" gear="1" kp="30000"/>
    <position name="LM_CTr" ctrllimited="true" ctrlrange="-3.141592654 3.141592654" joint="LM_CTr" gear="1" kp="30000"/>
    <position name="LH_CTr" ctrllimited="true" ctrlrange="-3.141592654 3.141592654" joint="LH_CTr" gear="1" kp="30000"/>
    <position name="RF_CTr" ctrllimited="true" ctrlrange="-3.141592654 3.141592654" joint="RF_CTr" gear="1" kp="30000"/>
    <position name="RM_CTr" ctrllimited="true" ctrlrange="-3.141592654 3.141592654" joint="RM_CTr" gear="1" kp="30000"/>
    <position name="RH_CTr" ctrllimited="true" ctrlrange="-3.141592654 3.141592654" joint="RH_CTr" gear="1" kp="30000"/>

    <position name="LF_ThC" ctrllimited="true" ctrlrange="-3.141592654 3.141592654" joint="LF_ThC" gear="1" kp="30000"/>
    <position name="LM_ThC" ctrllimited="true" ctrlrange="-3.141592654 3.141592654" joint="LM_ThC" gear="1" kp="30000"/>
    <position name="LH_ThC" ctrllimited="true" ctrlrange="-3.141592654 3.141592654" joint="LH_ThC" gear="1" kp="30000"/>
    <position name="RF_ThC" ctrllimited="true" ctrlrange="-3.141592654 3.141592654" joint="RF_ThC" gear="1" kp="30000"/>
    <position name="RM_ThC" ctrllimited="true" ctrlrange="-3.141592654 3.141592654" joint="RM_ThC" gear="1" kp="30000"/>
    <position name="RH_ThC" ctrllimited="true" ctrlrange="-3.141592654 3.141592654" joint="RH_ThC" gear="1" kp="30000"/>

    <position name="LF_FTi" ctrllimited="true" ctrlrange="-3.141592654 3.141592654" joint="LF_FTi" gear="1" kp="30000"/>
    <position name="LM_FTi" ctrllimited="true" ctrlrange="-3.141592654 3.141592654" joint="LM_FTi" gear="1" kp="30000"/>
    <position name="LH_FTi" ctrllimited="true" ctrlrange="-3.141592654 3.141592654" joint="LH_FTi" gear="1" kp="30000"/>
    <position name="RF_FTi" ctrllimited="true" ctrlrange="-3.141592654 3.141592654" joint="RF_FTi" gear="1" kp="30000"/>
    <position name="RM_FTi" ctrllimited="true" ctrlrange="-3.141592654 3.141592654" joint="RM_FTi" gear="1" kp="30000"/>
    <position name="RH_FTi" ctrllimited="true" ctrlrange="-3.141592654 3.141592654" joint="RH_FTi" gear="1" kp="30000"/>

    <velocity joint="LF_Sup" gear="1"/>
    <velocity joint="LM_Sup" gear="1"/>
    <velocity joint="LH_Sup" gear="1"/>
    <velocity joint="RF_Sup" gear="1"/>
    <velocity joint="RM_Sup" gear="1"/>
    <velocity joint="RH_Sup" gear="1"/>

    <velocity joint="LF_CTr" gear="1"/>
    <velocity joint="LM_CTr" gear="1"/>
    <velocity joint="LH_CTr" gear="1"/>
    <velocity joint="RF_CTr" gear="1"/>
    <velocity joint="RM_CTr" gear="1"/>
    <velocity joint="RH_CTr" gear="1"/>

    <velocity joint="LF_ThC" gear="1"/>
    <velocity joint="LM_ThC" gear="1"/>
    <velocity joint="LH_ThC" gear="1"/>
    <velocity joint="RF_ThC" gear="1"/>
    <velocity joint="RM_ThC" gear="1"/>
    <velocity joint="RH_ThC" gear="1"/>

    <velocity joint="LF_FTi" gear="1"/>
    <velocity joint="LM_FTi" gear="1"/>
    <velocity joint="LH_FTi" gear="1"/>
    <velocity joint="RF_FTi" gear="1"/>
    <velocity joint="RM_FTi" gear="1"/>
    <velocity joint="RH_FTi" gear="1"/>
  </actuator>

  <sensor>
    <!-- <actuatorfrc actuator="LF_Sup" name="LF_Sup"/>
    <actuatorfrc actuator="LM_Sup" name="LM_Sup"/>
    <actuatorfrc actuator="LH_Sup" name="LH_Sup"/>
    <actuatorfrc actuator="RF_Sup" name="RF_Sup"/>
    <actuatorfrc actuator="RM_Sup" name="RM_Sup"/>
    <actuatorfrc actuator="RH_Sup" name="RH_Sup"/>

    <actuatorfrc actuator="LF_CTr" name="LF_CTr"/>
    <actuatorfrc actuator="LM_CTr" name="LM_CTr"/>
    <actuatorfrc actuator="LH_CTr" name="LH_CTr"/>
    <actuatorfrc actuator="RF_CTr" name="RF_CTr"/>
    <actuatorfrc actuator="RM_CTr" name="RM_CTr"/>
    <actuatorfrc actuator="RH_CTr" name="RH_CTr"/>

    <actuatorfrc actuator="LF_ThC" name="LF_ThC"/>
    <actuatorfrc actuator="LM_ThC" name="LM_ThC"/>
    <actuatorfrc actuator="LH_ThC" name="LH_ThC"/>
    <actuatorfrc actuator="RF_ThC" name="RF_ThC"/>
    <actuatorfrc actuator="RM_ThC" name="RM_ThC"/>
    <actuatorfrc actuator="RH_ThC" name="RH_ThC"/>

    <actuatorfrc actuator="LF_FTi" name="LF_FTi"/>
    <actuatorfrc actuator="LM_FTi" name="LM_FTi"/>
    <actuatorfrc actuator="LH_FTi" name="LH_FTi"/>
    <actuatorfrc actuator="RF_FTi" name="RF_FTi"/>
    <actuatorfrc actuator="RM_FTi" name="RM_FTi"/>
    <actuatorfrc actuator="RH_FTi" name="RH_FTi"/> -->

    <torque site="LF_Sup_site" name="LF_Sup"/>
    <torque site="LM_Sup_site" name="LM_Sup"/>
    <torque site="LH_Sup_site" name="LH_Sup"/>
    <torque site="RF_Sup_site" name="RF_Sup"/>
    <torque site="RM_Sup_site" name="RM_Sup"/>
    <torque site="RH_Sup_site" name="RH_Sup"/>

    <torque site="LF_CTr_site" name="LF_CTr"/>
    <torque site="LM_CTr_site" name="LM_CTr"/>
    <torque site="LH_CTr_site" name="LH_CTr"/>
    <torque site="RF_CTr_site" name="RF_CTr"/>
    <torque site="RM_CTr_site" name="RM_CTr"/>
    <torque site="RH_CTr_site" name="RH_CTr"/>

    <torque site="LF_ThC_site" name="LF_ThC"/>
    <torque site="LM_ThC_site" name="LM_ThC"/>
    <torque site="LH_ThC_site" name="LH_ThC"/>
    <torque site="RF_ThC_site" name="RF_ThC"/>
    <torque site="RM_ThC_site" name="RM_ThC"/>
    <torque site="RH_ThC_site" name="RH_ThC"/>

    <torque site="LF_FTi_site" name="LF_FTi"/>
    <torque site="LM_FTi_site" name="LM_FTi"/>
    <torque site="LH_FTi_site" name="LH_FTi"/>
    <torque site="RF_FTi_site" name="RF_FTi"/>
    <torque site="RM_FTi_site" name="RM_FTi"/>
    <torque site="RH_FTi_site" name="RH_FTi"/>
  </sensor>
</mujoco>